<sdf version='1.7'>
  <world name='default'>
    <physics name='default_physics' default='0' type='ode'>
      <max_step_size>0.001</max_step_size>
      <real_time_factor>1</real_time_factor>
      <real_time_update_rate>1000</real_time_update_rate>
    </physics>
    <scene>
      <ambient>0.4 0.4 0.4 1</ambient>
      <background>0.7 0.7 0.7 1</background>
      <shadows>1</shadows>
    </scene>
    <light name='sun' type='directional'>
      <cast_shadows>1</cast_shadows>
      <pose>0 0 10 0 -0 0</pose>
      <diffuse>0.8 0.8 0.8 1</diffuse>
      <specular>0.1 0.1 0.1 1</specular>
      <attenuation>
        <range>1000</range>
        <constant>0.9</constant>
        <linear>0.01</linear>
        <quadratic>0.001</quadratic>
      </attenuation>
      <direction>-0.5 0.5 -1</direction>
      <spot>
        <inner_angle>0</inner_angle>
        <outer_angle>0</outer_angle>
        <falloff>0</falloff>
      </spot>
    </light>
    <model name='ground_plane'>
      <static>1</static>
      <link name='link'>
        <collision name='collision'>
          <geometry>
            <plane>
              <normal>0 0 1</normal>
              <size>100 100</size>
            </plane>
          </geometry>
          <surface>
            <contact>
              <collide_bitmask>65535</collide_bitmask>
              <ode/>
            </contact>
            <friction>
              <ode>
                <mu>100</mu>
                <mu2>50</mu2>
              </ode>
              <torsional>
                <ode/>
              </torsional>
            </friction>
            <bounce/>
          </surface>
          <max_contacts>10</max_contacts>
        </collision>
        <visual name='visual'>
          <cast_shadows>0</cast_shadows>
          <geometry>
            <plane>
              <normal>0 0 1</normal>
              <size>100 100</size>
            </plane>
          </geometry>
          <material>
            <script>
              <uri>file://media/materials/scripts/gazebo.material</uri>
              <name>Gazebo/Grey</name>
            </script>
          </material>
        </visual>
        <self_collide>0</self_collide>
        <enable_wind>0</enable_wind>
        <kinematic>0</kinematic>
      </link>
      <pose>0 0 -1 0 -0 0</pose>
    </model>
    <model name='miro'>
      <frame name='miro_body::__model__' attached_to='miro_body::body'>
        <pose relative_to='__model__'>0 0 0 0 -0 0</pose>
      </frame>
      <link name='miro_body::body'>
        <inertial>
          <pose>-0.06 0 0.05 0 -0 0</pose>
          <mass>1.5708</mass>
          <inertia>
            <ixx>0.00523599</ixx>
            <ixy>0</ixy>
            <ixz>0</ixz>
            <iyy>0.00523599</iyy>
            <iyz>0</iyz>
            <izz>0.00785398</izz>
          </inertia>
        </inertial>
        <visual name='visual_valance'>
          <pose>0 0 0 0 -0 0</pose>
          <geometry>
            <mesh>
              <uri>model://miro_model/meshes/valance.dae</uri>
            </mesh>
          </geometry>
          <material>
            <script>
              <uri>file://media/materials/scripts/gazebo.material</uri>
              <name>Gazebo/Grey</name>
            </script>
          </material>
        </visual>
        <collision name='collision_valance'>
          <pose>0 0 0 0 -0 0</pose>
          <geometry>
            <mesh>
              <uri>model://miro_model/meshes/valance_collision.dae</uri>
            </mesh>
          </geometry>
          <surface>
            <friction>
              <ode>
                <mu>0.1</mu>
                <mu2>0.1</mu2>
              </ode>
              <torsional>
                <ode/>
              </torsional>
            </friction>
            <contact>
              <ode/>
            </contact>
            <bounce/>
          </surface>
          <max_contacts>10</max_contacts>
        </collision>
        <visual name='visual_skirt_lh'>
          <pose>0 0 0 0 -0 0</pose>
          <geometry>
            <mesh>
              <uri>model://miro_model/meshes/skirt_lh.dae</uri>
            </mesh>
          </geometry>
          <material>
            <script>
              <uri>file://media/materials/scripts/gazebo.material</uri>
              <name>Gazebo/Grey</name>
            </script>
          </material>
        </visual>
        <visual name='visual_skirt_rh'>
          <pose>0 0 0 0 -0 0</pose>
          <geometry>
            <mesh>
              <uri>model://miro_model/meshes/skirt_rh.dae</uri>
            </mesh>
          </geometry>
          <material>
            <script>
              <uri>file://media/materials/scripts/gazebo.material</uri>
              <name>Gazebo/Grey</name>
            </script>
          </material>
        </visual>
        <visual name='visual_cliff_sensor_L_asm'>
          <pose>0 0 0 0 -0 0</pose>
          <geometry>
            <mesh>
              <uri>model://miro_model/meshes/cliff_sensor_L_asm.dae</uri>
            </mesh>
          </geometry>
          <material>
            <script>
              <uri>file://media/materials/scripts/gazebo.material</uri>
              <name>Gazebo/DarkGrey</name>
            </script>
          </material>
        </visual>
        <visual name='visual_cliff_sensor_R_asm'>
          <pose>0 0 0 0 -0 0</pose>
          <geometry>
            <mesh>
              <uri>model://miro_model/meshes/cliff_sensor_R_asm.dae</uri>
            </mesh>
          </geometry>
          <material>
            <script>
              <uri>file://media/materials/scripts/gazebo.material</uri>
              <name>Gazebo/DarkGrey</name>
            </script>
          </material>
        </visual>
        <visual name='visual_light_sensor_holder_asm_L'>
          <pose>0 0 0 0 -0 0</pose>
          <geometry>
            <mesh>
              <uri>model://miro_model/meshes/light_sensor_holder_asm_L.dae</uri>
            </mesh>
          </geometry>
          <material>
            <script>
              <uri>file://media/materials/scripts/gazebo.material</uri>
              <name>Gazebo/DarkGrey</name>
            </script>
          </material>
        </visual>
        <visual name='visual_light_sensor_holder_asm_R'>
          <pose>0 0 0 0 -0 0</pose>
          <geometry>
            <mesh>
              <uri>model://miro_model/meshes/light_sensor_holder_asm_R.dae</uri>
            </mesh>
          </geometry>
          <material>
            <script>
              <uri>file://media/materials/scripts/gazebo.material</uri>
              <name>Gazebo/DarkGrey</name>
            </script>
          </material>
        </visual>
        <visual name='visual_body_shell'>
          <pose>0 0 0 0 -0 0</pose>
          <geometry>
            <mesh>
              <uri>model://miro_model/meshes/body_shell.dae</uri>
            </mesh>
          </geometry>
          <material>
            <script>
              <uri>file://media/materials/scripts/gazebo.material</uri>
              <name>Gazebo/White</name>
            </script>
          </material>
        </visual>
        <collision name='collision_body_shell'>
          <pose>0 0 0 0 -0 0</pose>
          <geometry>
            <mesh>
              <uri>model://miro_model/meshes/body_shell_collision.dae</uri>
            </mesh>
          </geometry>
          <surface>
            <friction>
              <ode>
                <mu>0.1</mu>
                <mu2>0.1</mu2>
              </ode>
              <torsional>
                <ode/>
              </torsional>
            </friction>
            <contact>
              <ode/>
            </contact>
            <bounce/>
          </surface>
          <max_contacts>10</max_contacts>
        </collision>
        <visual name='visual_slider'>
          <pose>0 0 0 0 -0 0</pose>
          <geometry>
            <mesh>
              <uri>model://miro_model/meshes/slider.dae</uri>
            </mesh>
          </geometry>
          <material>
            <script>
              <uri>file://media/materials/scripts/gazebo.material</uri>
              <name>Gazebo/DarkGrey</name>
            </script>
          </material>
        </visual>
        <collision name='collision_slider'>
          <pose>-0.1075 0 0.0264 0 -0 0</pose>
          <geometry>
            <sphere>
              <radius>0.015</radius>
            </sphere>
          </geometry>
          <surface>
            <friction>
              <ode>
                <mu>0.01</mu>
                <mu2>0.01</mu2>
              </ode>
              <torsional>
                <ode/>
              </torsional>
            </friction>
            <contact>
              <ode/>
            </contact>
            <bounce/>
          </surface>
          <max_contacts>10</max_contacts>
        </collision>
        <sensor name='acc_body' type='imu'>
          <pose>0 0 0 0 -0 0</pose>
          <always_on>1</always_on>
          <update_rate>50</update_rate>
          <visualize>0</visualize>
          <imu/>
        </sensor>
        <sensor name='cliff_l' type='sonar'>
          <pose>0.062 0.055 0.085 0 -0.52 0</pose>
          <always_on>1</always_on>
          <update_rate>50</update_rate>
          <visualize>0</visualize>
          <sonar>
            <min>0</min>
            <max>0.5</max>
            <radius>0.025</radius>
          </sonar>
        </sensor>
        <sensor name='cliff_r' type='sonar'>
          <pose>0.062 -0.055 0.085 0 -0.52 0</pose>
          <always_on>1</always_on>
          <update_rate>50</update_rate>
          <visualize>0</visualize>
          <sonar>
            <min>0</min>
            <max>0.5</max>
            <radius>0.025</radius>
          </sonar>
        </sensor>
        <sensor name='lightfl' type='camera'>
          <pose>0.055 0.065 0.08 -0 -0.06 0.52</pose>
          <camera>
            <horizontal_fov>1.57</horizontal_fov>
            <image>
              <width>16</width>
              <height>12</height>
            </image>
            <clip>
              <near>0.01</near>
              <far>10</far>
            </clip>
          </camera>
          <always_on>1</always_on>
          <update_rate>5</update_rate>
          <visualize>0</visualize>
        </sensor>
        <sensor name='lightfr' type='camera'>
          <pose>0.055 -0.065 0.08 0 -0.06 -0.52</pose>
          <camera>
            <horizontal_fov>1.57</horizontal_fov>
            <image>
              <width>16</width>
              <height>12</height>
            </image>
            <clip>
              <near>0.01</near>
              <far>10</far>
            </clip>
          </camera>
          <always_on>1</always_on>
          <update_rate>5</update_rate>
          <visualize>0</visualize>
        </sensor>
        <sensor name='lightrl' type='camera'>
          <pose>-0.125 0.072 0.06 0 -0.26 2.61</pose>
          <camera>
            <horizontal_fov>1.57</horizontal_fov>
            <image>
              <width>16</width>
              <height>12</height>
            </image>
            <clip>
              <near>0.01</near>
              <far>10</far>
            </clip>
          </camera>
          <always_on>1</always_on>
          <update_rate>5</update_rate>
          <visualize>0</visualize>
        </sensor>
        <sensor name='lightrr' type='camera'>
          <pose>-0.125 -0.072 0.06 0 -0.26 -2.61</pose>
          <camera>
            <horizontal_fov>1.57</horizontal_fov>
            <image>
              <width>16</width>
              <height>12</height>
            </image>
            <clip>
              <near>0.01</near>
              <far>10</far>
            </clip>
          </camera>
          <always_on>1</always_on>
          <update_rate>5</update_rate>
          <visualize>0</visualize>
        </sensor>
        <pose relative_to='miro_body::__model__'>0 0 0 0 -0 0</pose>
        <self_collide>0</self_collide>
        <enable_wind>0</enable_wind>
        <kinematic>0</kinematic>
      </link>
      <link name='miro_body::wheel_lh'>
        <inertial>
          <pose>0.00063 0.07779 0.044838 0 -0 0</pose>
          <mass>0.134041</mass>
          <inertia>
            <ixx>0.00014298</ixx>
            <ixy>0</ixy>
            <ixz>0</ixz>
            <iyy>0.00014298</iyy>
            <iyz>0</iyz>
            <izz>0.00014298</izz>
          </inertia>
        </inertial>
        <visual name='visual_wheel_tyre_lh'>
          <pose>0 0 0 0 -0 0</pose>
          <geometry>
            <mesh>
              <uri>model://miro_model/meshes/wheel_tyre_lh.dae</uri>
            </mesh>
          </geometry>
          <material>
            <script>
              <uri>file://media/materials/scripts/gazebo.material</uri>
              <name>Gazebo/DarkGrey</name>
            </script>
          </material>
        </visual>
        <collision name='collision_wheel_tyre_lh'>
          <pose>0.00063 0.07779 0.044838 -1.5446 0 0</pose>
          <geometry>
            <cylinder>
              <radius>0.045</radius>
              <length>0.002</length>
            </cylinder>
          </geometry>
          <surface>
            <friction>
              <ode>
                <mu>1</mu>
                <mu2>1</mu2>
              </ode>
              <torsional>
                <ode/>
              </torsional>
            </friction>
            <contact>
              <ode/>
            </contact>
            <bounce/>
          </surface>
          <max_contacts>10</max_contacts>
        </collision>
        <visual name='visual_wheel_rim_lh'>
          <pose>0 0 0 0 -0 0</pose>
          <geometry>
            <mesh>
              <uri>model://miro_model/meshes/wheel_rim_lh.dae</uri>
            </mesh>
          </geometry>
          <material>
            <script>
              <uri>file://media/materials/scripts/gazebo.material</uri>
              <name>Gazebo/Grey</name>
            </script>
          </material>
        </visual>
        <pose relative_to='miro_body::__model__'>0 0 0 0 -0 0</pose>
        <self_collide>0</self_collide>
        <enable_wind>0</enable_wind>
        <kinematic>0</kinematic>
      </link>
      <link name='miro_body::wheel_rh'>
        <inertial>
          <pose>0.00063 -0.07779 0.044838 0 -0 0</pose>
          <mass>0.134041</mass>
          <inertia>
            <ixx>0.00014298</ixx>
            <ixy>0</ixy>
            <ixz>0</ixz>
            <iyy>0.00014298</iyy>
            <iyz>0</iyz>
            <izz>0.00014298</izz>
          </inertia>
        </inertial>
        <visual name='visual_wheel_tyre_rh'>
          <pose>0 0 0 0 -0 0</pose>
          <geometry>
            <mesh>
              <uri>model://miro_model/meshes/wheel_tyre_rh.dae</uri>
            </mesh>
          </geometry>
          <material>
            <script>
              <uri>file://media/materials/scripts/gazebo.material</uri>
              <name>Gazebo/DarkGrey</name>
            </script>
          </material>
        </visual>
        <collision name='collision_wheel_tyre_rh'>
          <pose>0.00063 -0.07779 0.044838 1.5446 -0 0</pose>
          <geometry>
            <cylinder>
              <radius>0.045</radius>
              <length>0.002</length>
            </cylinder>
          </geometry>
          <surface>
            <friction>
              <ode>
                <mu>1</mu>
                <mu2>1</mu2>
              </ode>
              <torsional>
                <ode/>
              </torsional>
            </friction>
            <contact>
              <ode/>
            </contact>
            <bounce/>
          </surface>
          <max_contacts>10</max_contacts>
        </collision>
        <visual name='visual_wheel_rim_rh'>
          <pose>0 0 0 0 -0 0</pose>
          <geometry>
            <mesh>
              <uri>model://miro_model/meshes/wheel_rim_rh.dae</uri>
            </mesh>
          </geometry>
          <material>
            <script>
              <uri>file://media/materials/scripts/gazebo.material</uri>
              <name>Gazebo/Grey</name>
            </script>
          </material>
        </visual>
        <pose relative_to='miro_body::__model__'>0 0 0 0 -0 0</pose>
        <self_collide>0</self_collide>
        <enable_wind>0</enable_wind>
        <kinematic>0</kinematic>
      </link>
      <joint name='miro_body::body_wheel_lh' type='revolute'>
        <pose>0.00063 0.07779 0.044838 0 -0 0</pose>
        <parent>miro_body::body</parent>
        <child>miro_body::wheel_lh</child>
        <axis>
          <xyz>0 0.999657 0.026185</xyz>
          <dynamics>
            <friction>0.1</friction>
            <damping>0.1</damping>
            <spring_reference>0</spring_reference>
            <spring_stiffness>0</spring_stiffness>
          </dynamics>
          <limit>
            <lower>-1e+16</lower>
            <upper>1e+16</upper>
          </limit>
        </axis>
      </joint>
      <joint name='miro_body::body_wheel_rh' type='revolute'>
        <pose>0.00063 -0.07779 0.044838 0 -0 0</pose>
        <parent>miro_body::body</parent>
        <child>miro_body::wheel_rh</child>
        <axis>
          <xyz>0 0.999657 -0.026185</xyz>
          <dynamics>
            <friction>0.1</friction>
            <damping>0.1</damping>
            <spring_reference>0</spring_reference>
            <spring_stiffness>0</spring_stiffness>
          </dynamics>
          <limit>
            <lower>-1e+16</lower>
            <upper>1e+16</upper>
          </limit>
        </axis>
      </joint>
      <frame name='miro_tail::__model__' attached_to='miro_tail::tail_gmbl'>
        <pose relative_to='__model__'>0 0 0 0 -0 0</pose>
      </frame>
      <link name='miro_tail::tail_gmbl'>
        <inertial>
          <pose>-0.143 0 0.085 0 -0 0</pose>
          <mass>0.056549</mass>
          <inertia>
            <ixx>3.393e-05</ixx>
            <ixy>0</ixy>
            <ixz>0</ixz>
            <iyy>3.393e-05</iyy>
            <iyz>0</iyz>
            <izz>3.393e-05</izz>
          </inertia>
        </inertial>
        <pose relative_to='miro_tail::__model__'>0 0 0 0 -0 0</pose>
        <self_collide>0</self_collide>
        <enable_wind>0</enable_wind>
        <kinematic>0</kinematic>
      </link>
      <joint name='miro_tail::body_tail_gmbl' type='revolute'>
        <pose>-0.143 0 0.085 0 -0 0</pose>
        <parent>miro_body::body</parent>
        <child>miro_tail::tail_gmbl</child>
        <axis>
          <xyz>0 1 0</xyz>
          <limit>
            <lower>-1.57</lower>
            <upper>1.57</upper>
          </limit>
          <dynamics>
            <friction>0.01</friction>
            <damping>0.02</damping>
            <spring_reference>0</spring_reference>
            <spring_stiffness>0</spring_stiffness>
          </dynamics>
        </axis>
      </joint>
      <link name='miro_tail::tail'>
        <inertial>
          <pose>-0.143 0 0.085 0 -0 0</pose>
          <mass>0.056549</mass>
          <inertia>
            <ixx>3.393e-05</ixx>
            <ixy>0</ixy>
            <ixz>0</ixz>
            <iyy>3.393e-05</iyy>
            <iyz>0</iyz>
            <izz>3.393e-05</izz>
          </inertia>
        </inertial>
        <visual name='visual_tail'>
          <pose>0 0 0 0 -0 0</pose>
          <geometry>
            <mesh>
              <uri>model://miro_model/meshes/tail.dae</uri>
            </mesh>
          </geometry>
          <material>
            <script>
              <uri>file://media/materials/scripts/gazebo.material</uri>
              <name>Gazebo/Grey</name>
            </script>
          </material>
        </visual>
        <collision name='collision_tail'>
          <pose>0 0 0 0 -0 0</pose>
          <geometry>
            <mesh>
              <uri>model://miro_model/meshes/tail_collision.dae</uri>
            </mesh>
          </geometry>
          <surface>
            <friction>
              <ode>
                <mu>0.1</mu>
                <mu2>0.1</mu2>
              </ode>
              <torsional>
                <ode/>
              </torsional>
            </friction>
            <contact>
              <ode/>
            </contact>
            <bounce/>
          </surface>
          <max_contacts>10</max_contacts>
        </collision>
        <pose relative_to='miro_tail::__model__'>0 0 0 0 -0 0</pose>
        <self_collide>0</self_collide>
        <enable_wind>0</enable_wind>
        <kinematic>0</kinematic>
      </link>
      <joint name='miro_tail::tail_gmbl_tail' type='revolute'>
        <pose>-0.143 0 0.085 0 -0 0</pose>
        <parent>miro_tail::tail_gmbl</parent>
        <child>miro_tail::tail</child>
        <axis>
          <xyz>0 0 1</xyz>
          <limit>
            <lower>-1.57</lower>
            <upper>1.57</upper>
          </limit>
          <dynamics>
            <friction>0.01</friction>
            <damping>0.02</damping>
            <spring_reference>0</spring_reference>
            <spring_stiffness>0</spring_stiffness>
          </dynamics>
        </axis>
      </joint>
      <joint name='body_neck' type='revolute'>
        <pose>-0.002 0 0.081 0 -0 0</pose>
        <parent>miro_body::body</parent>
        <child>miro_neck::neck</child>
        <axis>
          <xyz>0 1 0</xyz>
          <limit>
            <lower>0</lower>
            <upper>1.57</upper>
          </limit>
          <dynamics>
            <spring_stiffness>0.4</spring_stiffness>
            <spring_reference>0</spring_reference>
            <friction>0.01</friction>
            <damping>0.1</damping>
          </dynamics>
        </axis>
      </joint>
      <frame name='miro_neck::__model__' attached_to='miro_neck::neck'>
        <pose relative_to='__model__'>0 0 0 0 -0 0</pose>
      </frame>
      <link name='miro_neck::neck'>
        <inertial>
          <pose>-0.002 0 0.141 0 -0 0</pose>
          <mass>0.075398</mass>
          <inertia>
            <ixx>9.802e-05</ixx>
            <ixy>0</ixy>
            <ixz>0</ixz>
            <iyy>9.802e-05</iyy>
            <iyz>0</iyz>
            <izz>1.508e-05</izz>
          </inertia>
        </inertial>
        <pose relative_to='miro_neck::__model__'>0 0 0 0 -0 0</pose>
        <self_collide>0</self_collide>
        <enable_wind>0</enable_wind>
        <kinematic>0</kinematic>
      </link>
      <joint name='neck_gmbl' type='revolute'>
        <pose>-0.002 0 0.201 0 -0 0</pose>
        <parent>miro_neck::neck</parent>
        <child>miro_gmbl::gmbl</child>
        <axis>
          <xyz>0 0 1</xyz>
          <limit>
            <lower>-1.57</lower>
            <upper>1.57</upper>
          </limit>
          <dynamics>
            <friction>0.01</friction>
            <damping>0.1</damping>
            <spring_reference>0</spring_reference>
            <spring_stiffness>0</spring_stiffness>
          </dynamics>
        </axis>
      </joint>
      <frame name='miro_gmbl::__model__' attached_to='miro_gmbl::gmbl'>
        <pose relative_to='__model__'>0 0 0 0 -0 0</pose>
      </frame>
      <link name='miro_gmbl::gmbl'>
        <inertial>
          <pose>-0.002 0 0.171 0 -0 0</pose>
          <mass>0.03927</mass>
          <inertia>
            <ixx>2.487e-05</ixx>
            <ixy>0</ixy>
            <ixz>0</ixz>
            <iyy>2.487e-05</iyy>
            <iyz>0</iyz>
            <izz>4.909e-05</izz>
          </inertia>
        </inertial>
        <visual name='visual_collar'>
          <pose>0 0 0 0 -0 0</pose>
          <geometry>
            <mesh>
              <uri>model://miro_model/meshes/collar.dae</uri>
            </mesh>
          </geometry>
          <material>
            <script>
              <uri>file://media/materials/scripts/gazebo.material</uri>
              <name>Gazebo/Red</name>
            </script>
          </material>
        </visual>
        <pose relative_to='miro_gmbl::__model__'>0 0 0 0 -0 0</pose>
        <self_collide>0</self_collide>
        <enable_wind>0</enable_wind>
        <kinematic>0</kinematic>
      </link>
      <joint name='gmbl_head' type='revolute'>
        <pose>-0.002 0 0.201 0 -0 0</pose>
        <parent>miro_gmbl::gmbl</parent>
        <child>miro_head::head</child>
        <axis>
          <xyz>0 1 0</xyz>
          <limit>
            <lower>-1.57</lower>
            <upper>1.57</upper>
          </limit>
          <dynamics>
            <spring_stiffness>0.1</spring_stiffness>
            <spring_reference>-0.5</spring_reference>
            <friction>0.01</friction>
            <damping>0.1</damping>
          </dynamics>
        </axis>
      </joint>
      <frame name='miro_head::__model__' attached_to='miro_head::head'>
        <pose relative_to='__model__'>0 0 0 0 -0 0</pose>
      </frame>
      <link name='miro_head::head'>
        <inertial>
          <pose>-0.002 0 0.221 0 -0 0</pose>
          <mass>0.261799</mass>
          <inertia>
            <ixx>0.00043633</ixx>
            <ixy>0</ixy>
            <ixz>0</ixz>
            <iyy>0.00043633</iyy>
            <iyz>0</iyz>
            <izz>0.00043633</izz>
          </inertia>
        </inertial>
        <visual name='visual_head_lower'>
          <pose>0 0 0 0 -0 0</pose>
          <geometry>
            <mesh>
              <uri>model://miro_model/meshes/head_lower.dae</uri>
            </mesh>
          </geometry>
          <material>
            <script>
              <uri>file://media/materials/scripts/gazebo.material</uri>
              <name>Gazebo/White</name>
            </script>
          </material>
        </visual>
        <collision name='collision_head_lower'>
          <pose>0 0 0 0 -0 0</pose>
          <geometry>
            <mesh>
              <uri>model://miro_model/meshes/head_lower_collision.dae</uri>
            </mesh>
          </geometry>
          <surface>
            <friction>
              <ode>
                <mu>0.1</mu>
                <mu2>0.1</mu2>
              </ode>
              <torsional>
                <ode/>
              </torsional>
            </friction>
            <contact>
              <ode/>
            </contact>
            <bounce/>
          </surface>
          <max_contacts>10</max_contacts>
        </collision>
        <visual name='visual_head_upper'>
          <pose>0 0 0 0 -0 0</pose>
          <geometry>
            <mesh>
              <uri>model://miro_model/meshes/head_upper.dae</uri>
            </mesh>
          </geometry>
          <material>
            <script>
              <uri>file://media/materials/scripts/gazebo.material</uri>
              <name>Gazebo/White</name>
            </script>
          </material>
        </visual>
        <collision name='collision_head_upper'>
          <pose>0 0 0 0 -0 0</pose>
          <geometry>
            <mesh>
              <uri>model://miro_model/meshes/head_upper_collision.dae</uri>
            </mesh>
          </geometry>
          <surface>
            <friction>
              <ode>
                <mu>0.1</mu>
                <mu2>0.1</mu2>
              </ode>
              <torsional>
                <ode/>
              </torsional>
            </friction>
            <contact>
              <ode/>
            </contact>
            <bounce/>
          </surface>
          <max_contacts>10</max_contacts>
        </collision>
        <visual name='visual_eyelid_lower_lh'>
          <pose>0 0 0 0 -0 0</pose>
          <geometry>
            <mesh>
              <uri>model://miro_model/meshes/eyelid_lower_lh.dae</uri>
            </mesh>
          </geometry>
          <material>
            <script>
              <uri>file://media/materials/scripts/gazebo.material</uri>
              <name>Gazebo/White</name>
            </script>
          </material>
        </visual>
        <visual name='visual_eyelid_lower_rh'>
          <pose>0 0 0 0 -0 0</pose>
          <geometry>
            <mesh>
              <uri>model://miro_model/meshes/eyelid_lower_rh.dae</uri>
            </mesh>
          </geometry>
          <material>
            <script>
              <uri>file://media/materials/scripts/gazebo.material</uri>
              <name>Gazebo/White</name>
            </script>
          </material>
        </visual>
        <visual name='visual_nose'>
          <pose>0 0 0 0 -0 0</pose>
          <geometry>
            <mesh>
              <uri>model://miro_model/meshes/nose.dae</uri>
            </mesh>
          </geometry>
          <material>
            <script>
              <uri>file://media/materials/scripts/gazebo.material</uri>
              <name>Gazebo/Grey</name>
            </script>
          </material>
        </visual>
        <collision name='collision_nose'>
          <pose>0 0 0 0 -0 0</pose>
          <geometry>
            <mesh>
              <uri>model://miro_model/meshes/nose_collision.dae</uri>
            </mesh>
          </geometry>
          <surface>
            <friction>
              <ode>
                <mu>0.3</mu>
                <mu2>0.3</mu2>
              </ode>
              <torsional>
                <ode/>
              </torsional>
            </friction>
            <contact>
              <ode/>
            </contact>
            <bounce/>
          </surface>
          <max_contacts>10</max_contacts>
        </collision>
        <visual name='visual_1'>
          <pose>0.029 0.033 0.252 0 -0 0</pose>
          <geometry>
            <sphere>
              <radius>0.018</radius>
            </sphere>
          </geometry>
          <material>
            <script>
              <uri>file://media/materials/scripts/gazebo.material</uri>
              <name>Gazebo/White</name>
            </script>
          </material>
        </visual>
        <visual name='visual_2'>
          <pose>0.0315 0.036 0.254 0 -0 0</pose>
          <geometry>
            <sphere>
              <radius>0.015</radius>
            </sphere>
          </geometry>
          <material>
            <script>
              <uri>file://media/materials/scripts/gazebo.material</uri>
              <name>Gazebo/DarkGrey</name>
            </script>
          </material>
        </visual>
        <visual name='visual_3'>
          <pose>0.029 -0.033 0.252 0 -0 0</pose>
          <geometry>
            <sphere>
              <radius>0.018</radius>
            </sphere>
          </geometry>
          <material>
            <script>
              <uri>file://media/materials/scripts/gazebo.material</uri>
              <name>Gazebo/White</name>
            </script>
          </material>
        </visual>
        <visual name='visual_4'>
          <pose>0.0315 -0.036 0.254 0 -0 0</pose>
          <geometry>
            <sphere>
              <radius>0.015</radius>
            </sphere>
          </geometry>
          <material>
            <script>
              <uri>file://media/materials/scripts/gazebo.material</uri>
              <name>Gazebo/DarkGrey</name>
            </script>
          </material>
        </visual>
        <sensor name='eye_l' type='wideanglecamera'>
          <pose>0.0377 0.0431 0.2595 -0.4262 -0.6816 0.6244</pose>
          <camera>
            <horizontal_fov>2.0944</horizontal_fov>
            <image>
              <width>1280</width>
              <height>720</height>
            </image>
            <clip>
              <near>0.006</near>
              <far>100</far>
            </clip>
            <lens>
              <type>custom</type>
              <scale_to_hfov>1</scale_to_hfov>
              <custom_function>
                <c1>2</c1>
                <c2>1.25</c2>
                <c3>0</c3>
                <f>1</f>
                <fun>sin</fun>
              </custom_function>
            </lens>
          </camera>
          <always_on>1</always_on>
          <update_rate>10</update_rate>
          <visualize>0</visualize>
        </sensor>
        <sensor name='eye_r' type='wideanglecamera'>
          <pose>0.0377 -0.0431 0.2595 0.4261 -0.6816 -0.6244</pose>
          <camera>
            <horizontal_fov>2.0944</horizontal_fov>
            <image>
              <width>1280</width>
              <height>720</height>
            </image>
            <clip>
              <near>0.006</near>
              <far>100</far>
            </clip>
            <lens>
              <type>custom</type>
              <scale_to_hfov>1</scale_to_hfov>
              <custom_function>
                <c1>2</c1>
                <c2>1.25</c2>
                <c3>0</c3>
                <f>1</f>
                <fun>sin</fun>
              </custom_function>
            </lens>
          </camera>
          <always_on>1</always_on>
          <update_rate>10</update_rate>
          <visualize>0</visualize>
        </sensor>
        <sensor name='eye_l_narrow' type='camera'>
          <pose>0.0377 0.0431 0.2595 -0.4262 -0.6816 0.6244</pose>
          <camera>
            <horizontal_fov>2.0944</horizontal_fov>
            <image>
              <width>1280</width>
              <height>720</height>
            </image>
            <clip>
              <near>0.006</near>
              <far>100</far>
            </clip>
          </camera>
          <always_on>1</always_on>
          <update_rate>10</update_rate>
          <visualize>0</visualize>
        </sensor>
        <sensor name='eye_r_narrow' type='camera'>
          <pose>0.0377 -0.0431 0.2595 0.4261 -0.6816 -0.6244</pose>
          <camera>
            <horizontal_fov>2.0944</horizontal_fov>
            <image>
              <width>1280</width>
              <height>720</height>
            </image>
            <clip>
              <near>0.006</near>
              <far>100</far>
            </clip>
          </camera>
          <always_on>1</always_on>
          <update_rate>10</update_rate>
          <visualize>0</visualize>
        </sensor>
        <sensor name='gaze' type='camera'>
          <pose>0.0577 0 0.2795 0 -0.785398 0</pose>
          <camera>
            <horizontal_fov>1</horizontal_fov>
            <image>
              <width>1280</width>
              <height>720</height>
            </image>
            <clip>
              <near>0.001</near>
              <far>100</far>
            </clip>
          </camera>
          <always_on>1</always_on>
          <update_rate>10</update_rate>
          <visualize>0</visualize>
        </sensor>
        <sensor name='overhead' type='camera'>
          <pose>0 0 1 0 1.22 0</pose>
          <camera>
            <horizontal_fov>1.0472</horizontal_fov>
            <image>
              <width>1280</width>
              <height>720</height>
            </image>
            <clip>
              <near>0.01</near>
              <far>2</far>
            </clip>
          </camera>
          <always_on>1</always_on>
          <update_rate>10</update_rate>
          <visualize>0</visualize>
        </sensor>
        <sensor name='acc_head' type='imu'>
          <pose>0 0 0 0 -0 0</pose>
          <always_on>1</always_on>
          <update_rate>50</update_rate>
          <visualize>0</visualize>
          <imu/>
        </sensor>
        <sensor name='sonar' type='sonar'>
          <pose>0.1 0 0.235 3.14159 -1.57079 3.14159</pose>
          <always_on>1</always_on>
          <update_rate>50</update_rate>
          <visualize>0</visualize>
          <sonar>
            <min>0</min>
            <max>1</max>
            <radius>0.309</radius>
          </sonar>
        </sensor>
        <pose relative_to='miro_head::__model__'>0 0 0 0 -0 0</pose>
        <self_collide>0</self_collide>
        <enable_wind>0</enable_wind>
        <kinematic>0</kinematic>
      </link>
      <link name='miro_head::eyelid_lh'>
        <inertial>
          <pose>0.029 0.032 0.252 0 -0 0</pose>
          <mass>0.016755</mass>
          <inertia>
            <ixx>4.47e-06</ixx>
            <ixy>0</ixy>
            <ixz>0</ixz>
            <iyy>4.47e-06</iyy>
            <iyz>0</iyz>
            <izz>4.47e-06</izz>
          </inertia>
        </inertial>
        <visual name='visual_eyelid_lh'>
          <pose>0 0 0 0 -0 0</pose>
          <geometry>
            <mesh>
              <uri>model://miro_model/meshes/eyelid_lh.dae</uri>
            </mesh>
          </geometry>
          <material>
            <script>
              <uri>file://media/materials/scripts/gazebo.material</uri>
              <name>Gazebo/White</name>
            </script>
          </material>
        </visual>
        <pose relative_to='miro_head::__model__'>0 0 0 0 -0 0</pose>
        <self_collide>0</self_collide>
        <enable_wind>0</enable_wind>
        <kinematic>0</kinematic>
      </link>
      <link name='miro_head::eyelid_rh'>
        <inertial>
          <pose>0.029 -0.032 0.252 0 -0 0</pose>
          <mass>0.016755</mass>
          <inertia>
            <ixx>4.47e-06</ixx>
            <ixy>0</ixy>
            <ixz>0</ixz>
            <iyy>4.47e-06</iyy>
            <iyz>0</iyz>
            <izz>4.47e-06</izz>
          </inertia>
        </inertial>
        <visual name='visual_eyelid_rh'>
          <pose>0 0 0 0 -0 0</pose>
          <geometry>
            <mesh>
              <uri>model://miro_model/meshes/eyelid_rh.dae</uri>
            </mesh>
          </geometry>
          <material>
            <script>
              <uri>file://media/materials/scripts/gazebo.material</uri>
              <name>Gazebo/White</name>
            </script>
          </material>
        </visual>
        <pose relative_to='miro_head::__model__'>0 0 0 0 -0 0</pose>
        <self_collide>0</self_collide>
        <enable_wind>0</enable_wind>
        <kinematic>0</kinematic>
      </link>
      <joint name='miro_head::head_eyelid_lh' type='revolute'>
        <pose>0.029 0.032 0.252 0 -0 0</pose>
        <parent>miro_head::head</parent>
        <child>miro_head::eyelid_lh</child>
        <axis>
          <xyz>-0.675 0.675 -0.2978</xyz>
          <limit>
            <lower>-1.57</lower>
            <upper>1.57</upper>
          </limit>
          <dynamics>
            <friction>0.1</friction>
            <damping>0.1</damping>
            <spring_reference>-0.5</spring_reference>
            <spring_stiffness>0.02</spring_stiffness>
          </dynamics>
        </axis>
        <physics>
          <ode>
            <cfm_damping>1</cfm_damping>
            <implicit_spring_damper>1</implicit_spring_damper>
            <limit>
              <cfm>0</cfm>
              <erp>0.2</erp>
            </limit>
          </ode>
        </physics>
      </joint>
      <joint name='miro_head::head_eyelid_rh' type='revolute'>
        <pose>0.029 -0.032 0.252 0 -0 0</pose>
        <parent>miro_head::head</parent>
        <child>miro_head::eyelid_rh</child>
        <axis>
          <xyz>0.675 0.675 0.2978</xyz>
          <limit>
            <lower>-1.57</lower>
            <upper>1.57</upper>
          </limit>
          <dynamics>
            <friction>0.1</friction>
            <damping>0.1</damping>
            <spring_reference>-0.5</spring_reference>
            <spring_stiffness>0.02</spring_stiffness>
          </dynamics>
        </axis>
        <physics>
          <ode>
            <cfm_damping>1</cfm_damping>
            <implicit_spring_damper>1</implicit_spring_damper>
            <limit>
              <cfm>0</cfm>
              <erp>0.2</erp>
            </limit>
          </ode>
        </physics>
      </joint>
      <link name='miro_head::ear_lh'>
        <inertial>
          <pose>-0.0437 0.0474 0.2773 0 -0 0</pose>
          <mass>0.056549</mass>
          <inertia>
            <ixx>3.393e-05</ixx>
            <ixy>0</ixy>
            <ixz>0</ixz>
            <iyy>3.393e-05</iyy>
            <iyz>0</iyz>
            <izz>3.393e-05</izz>
          </inertia>
        </inertial>
        <visual name='visual_ear_lh'>
          <pose>0 0 0 0 -0 0</pose>
          <geometry>
            <mesh>
              <uri>model://miro_model/meshes/ear_lh.dae</uri>
            </mesh>
          </geometry>
          <material>
            <script>
              <uri>file://media/materials/scripts/gazebo.material</uri>
              <name>Gazebo/Grey</name>
            </script>
          </material>
        </visual>
        <collision name='collision_ear_lh'>
          <pose>0 0 0 0 -0 0</pose>
          <geometry>
            <mesh>
              <uri>model://miro_model/meshes/ear_lh_collision.dae</uri>
            </mesh>
          </geometry>
          <surface>
            <friction>
              <ode>
                <mu>0.3</mu>
                <mu2>0.3</mu2>
              </ode>
              <torsional>
                <ode/>
              </torsional>
            </friction>
            <contact>
              <ode/>
            </contact>
            <bounce/>
          </surface>
          <max_contacts>10</max_contacts>
        </collision>
        <pose relative_to='miro_head::__model__'>0 0 0 0 -0 0</pose>
        <self_collide>0</self_collide>
        <enable_wind>0</enable_wind>
        <kinematic>0</kinematic>
      </link>
      <link name='miro_head::ear_rh'>
        <inertial>
          <pose>-0.0437 -0.0474 0.2773 0 -0 0</pose>
          <mass>0.056549</mass>
          <inertia>
            <ixx>3.393e-05</ixx>
            <ixy>0</ixy>
            <ixz>0</ixz>
            <iyy>3.393e-05</iyy>
            <iyz>0</iyz>
            <izz>3.393e-05</izz>
          </inertia>
        </inertial>
        <visual name='visual_ear_rh'>
          <pose>0 0 0 0 -0 0</pose>
          <geometry>
            <mesh>
              <uri>model://miro_model/meshes/ear_rh.dae</uri>
            </mesh>
          </geometry>
          <material>
            <script>
              <uri>file://media/materials/scripts/gazebo.material</uri>
              <name>Gazebo/Grey</name>
            </script>
          </material>
        </visual>
        <collision name='collision_ear_rh'>
          <pose>0 0 0 0 -0 0</pose>
          <geometry>
            <mesh>
              <uri>model://miro_model/meshes/ear_rh_collision.dae</uri>
            </mesh>
          </geometry>
          <surface>
            <friction>
              <ode>
                <mu>0.3</mu>
                <mu2>0.3</mu2>
              </ode>
              <torsional>
                <ode/>
              </torsional>
            </friction>
            <contact>
              <ode/>
            </contact>
            <bounce/>
          </surface>
          <max_contacts>10</max_contacts>
        </collision>
        <pose relative_to='miro_head::__model__'>0 0 0 0 -0 0</pose>
        <self_collide>0</self_collide>
        <enable_wind>0</enable_wind>
        <kinematic>0</kinematic>
      </link>
      <joint name='miro_head::head_ear_lh' type='revolute'>
        <pose>-0.0437 0.0474 0.2773 0 -0 0</pose>
        <parent>miro_head::head</parent>
        <child>miro_head::ear_lh</child>
        <axis>
          <xyz>-0.573 0.4344 0.6949</xyz>
          <limit>
            <lower>-1.57</lower>
            <upper>1.57</upper>
          </limit>
          <dynamics>
            <friction>0.01</friction>
            <damping>0.001</damping>
            <spring_reference>0</spring_reference>
            <spring_stiffness>0</spring_stiffness>
          </dynamics>
        </axis>
      </joint>
      <joint name='miro_head::head_ear_rh' type='revolute'>
        <pose>-0.0437 -0.0474 0.2773 0 -0 0</pose>
        <parent>miro_head::head</parent>
        <child>miro_head::ear_rh</child>
        <axis>
          <xyz>-0.573 -0.4344 0.6949</xyz>
          <limit>
            <lower>-1.57</lower>
            <upper>1.57</upper>
          </limit>
          <dynamics>
            <friction>0.01</friction>
            <damping>0.001</damping>
            <spring_reference>0</spring_reference>
            <spring_stiffness>0</spring_stiffness>
          </dynamics>
        </axis>
      </joint>
      <plugin name='miro_model' filename='libmiro_gazebo.so'/>
      <pose>0 0 0 0 -0 0</pose>
    </model>
    <gravity>0 0 -9.8</gravity>
    <magnetic_field>6e-06 2.3e-05 -4.2e-05</magnetic_field>
    <atmosphere type='adiabatic'/>
    <spherical_coordinates>
      <surface_model>EARTH_WGS84</surface_model>
      <latitude_deg>0</latitude_deg>
      <longitude_deg>0</longitude_deg>
      <elevation>0</elevation>
      <heading_deg>0</heading_deg>
    </spherical_coordinates>
    <gui fullscreen='0'>
      <camera name='user_camera'>
        <pose>4.88362 -0.812297 8.809 -0 1.03164 3.13221</pose>
        <view_controller>orbit</view_controller>
        <projection_type>perspective</projection_type>
      </camera>
    </gui>
    <wind/>
    <model name='miro_football_pitch'>
      <static>1</static>
      <link name='main'>
        <visual name='visual_cqr_panel'>
          <pose>-1.625 1.3 0 0 -0 1.5708</pose>
          <geometry>
            <mesh>
              <uri>model://miro_football_pitch/meshes/cqr_panel.dae</uri>
            </mesh>
          </geometry>
        </visual>
        <collision name='collision_cqr_panel'>
          <pose>-1.625 1.3 0 0 -0 1.5708</pose>
          <geometry>
            <mesh>
              <uri>model://miro_football_pitch/meshes/cqr_panel.dae</uri>
            </mesh>
          </geometry>
          <surface>
            <friction>
              <ode>
                <mu>0.1</mu>
                <mu2>0.1</mu2>
              </ode>
              <torsional>
                <ode/>
              </torsional>
            </friction>
            <contact>
              <ode/>
            </contact>
            <bounce/>
          </surface>
          <max_contacts>10</max_contacts>
        </collision>
        <visual name='visual_1'>
          <pose>-1.625 -1.3 0 0 0 -1.5708</pose>
          <geometry>
            <mesh>
              <uri>model://miro_football_pitch/meshes/cqr_panel.dae</uri>
            </mesh>
          </geometry>
        </visual>
        <collision name='collision_1'>
          <pose>-1.625 -1.3 0 0 0 -1.5708</pose>
          <geometry>
            <mesh>
              <uri>model://miro_football_pitch/meshes/cqr_panel.dae</uri>
            </mesh>
          </geometry>
          <surface>
            <friction>
              <ode>
                <mu>0.1</mu>
                <mu2>0.1</mu2>
              </ode>
              <torsional>
                <ode/>
              </torsional>
            </friction>
            <contact>
              <ode/>
            </contact>
            <bounce/>
          </surface>
          <max_contacts>10</max_contacts>
        </collision>
        <visual name='visual_2'>
          <pose>-0.975 1.3 0 0 -0 1.5708</pose>
          <geometry>
            <mesh>
              <uri>model://miro_football_pitch/meshes/cqr_panel.dae</uri>
            </mesh>
          </geometry>
        </visual>
        <collision name='collision_2'>
          <pose>-0.975 1.3 0 0 -0 1.5708</pose>
          <geometry>
            <mesh>
              <uri>model://miro_football_pitch/meshes/cqr_panel.dae</uri>
            </mesh>
          </geometry>
          <surface>
            <friction>
              <ode>
                <mu>0.1</mu>
                <mu2>0.1</mu2>
              </ode>
              <torsional>
                <ode/>
              </torsional>
            </friction>
            <contact>
              <ode/>
            </contact>
            <bounce/>
          </surface>
          <max_contacts>10</max_contacts>
        </collision>
        <visual name='visual_3'>
          <pose>-0.975 -1.3 0 0 0 -1.5708</pose>
          <geometry>
            <mesh>
              <uri>model://miro_football_pitch/meshes/cqr_panel.dae</uri>
            </mesh>
          </geometry>
        </visual>
        <collision name='collision_3'>
          <pose>-0.975 -1.3 0 0 0 -1.5708</pose>
          <geometry>
            <mesh>
              <uri>model://miro_football_pitch/meshes/cqr_panel.dae</uri>
            </mesh>
          </geometry>
          <surface>
            <friction>
              <ode>
                <mu>0.1</mu>
                <mu2>0.1</mu2>
              </ode>
              <torsional>
                <ode/>
              </torsional>
            </friction>
            <contact>
              <ode/>
            </contact>
            <bounce/>
          </surface>
          <max_contacts>10</max_contacts>
        </collision>
        <visual name='visual_4'>
          <pose>-0.325 1.3 0 0 -0 1.5708</pose>
          <geometry>
            <mesh>
              <uri>model://miro_football_pitch/meshes/cqr_panel.dae</uri>
            </mesh>
          </geometry>
        </visual>
        <collision name='collision_4'>
          <pose>-0.325 1.3 0 0 -0 1.5708</pose>
          <geometry>
            <mesh>
              <uri>model://miro_football_pitch/meshes/cqr_panel.dae</uri>
            </mesh>
          </geometry>
          <surface>
            <friction>
              <ode>
                <mu>0.1</mu>
                <mu2>0.1</mu2>
              </ode>
              <torsional>
                <ode/>
              </torsional>
            </friction>
            <contact>
              <ode/>
            </contact>
            <bounce/>
          </surface>
          <max_contacts>10</max_contacts>
        </collision>
        <visual name='visual_5'>
          <pose>-0.325 -1.3 0 0 0 -1.5708</pose>
          <geometry>
            <mesh>
              <uri>model://miro_football_pitch/meshes/cqr_panel.dae</uri>
            </mesh>
          </geometry>
        </visual>
        <collision name='collision_5'>
          <pose>-0.325 -1.3 0 0 0 -1.5708</pose>
          <geometry>
            <mesh>
              <uri>model://miro_football_pitch/meshes/cqr_panel.dae</uri>
            </mesh>
          </geometry>
          <surface>
            <friction>
              <ode>
                <mu>0.1</mu>
                <mu2>0.1</mu2>
              </ode>
              <torsional>
                <ode/>
              </torsional>
            </friction>
            <contact>
              <ode/>
            </contact>
            <bounce/>
          </surface>
          <max_contacts>10</max_contacts>
        </collision>
        <visual name='visual_6'>
          <pose>0.325 1.3 0 0 -0 1.5708</pose>
          <geometry>
            <mesh>
              <uri>model://miro_football_pitch/meshes/cqr_panel.dae</uri>
            </mesh>
          </geometry>
        </visual>
        <collision name='collision_6'>
          <pose>0.325 1.3 0 0 -0 1.5708</pose>
          <geometry>
            <mesh>
              <uri>model://miro_football_pitch/meshes/cqr_panel.dae</uri>
            </mesh>
          </geometry>
          <surface>
            <friction>
              <ode>
                <mu>0.1</mu>
                <mu2>0.1</mu2>
              </ode>
              <torsional>
                <ode/>
              </torsional>
            </friction>
            <contact>
              <ode/>
            </contact>
            <bounce/>
          </surface>
          <max_contacts>10</max_contacts>
        </collision>
        <visual name='visual_7'>
          <pose>0.325 -1.3 0 0 0 -1.5708</pose>
          <geometry>
            <mesh>
              <uri>model://miro_football_pitch/meshes/cqr_panel.dae</uri>
            </mesh>
          </geometry>
        </visual>
        <collision name='collision_7'>
          <pose>0.325 -1.3 0 0 0 -1.5708</pose>
          <geometry>
            <mesh>
              <uri>model://miro_football_pitch/meshes/cqr_panel.dae</uri>
            </mesh>
          </geometry>
          <surface>
            <friction>
              <ode>
                <mu>0.1</mu>
                <mu2>0.1</mu2>
              </ode>
              <torsional>
                <ode/>
              </torsional>
            </friction>
            <contact>
              <ode/>
            </contact>
            <bounce/>
          </surface>
          <max_contacts>10</max_contacts>
        </collision>
        <visual name='visual_8'>
          <pose>0.975 1.3 0 0 -0 1.5708</pose>
          <geometry>
            <mesh>
              <uri>model://miro_football_pitch/meshes/cqr_panel.dae</uri>
            </mesh>
          </geometry>
        </visual>
        <collision name='collision_8'>
          <pose>0.975 1.3 0 0 -0 1.5708</pose>
          <geometry>
            <mesh>
              <uri>model://miro_football_pitch/meshes/cqr_panel.dae</uri>
            </mesh>
          </geometry>
          <surface>
            <friction>
              <ode>
                <mu>0.1</mu>
                <mu2>0.1</mu2>
              </ode>
              <torsional>
                <ode/>
              </torsional>
            </friction>
            <contact>
              <ode/>
            </contact>
            <bounce/>
          </surface>
          <max_contacts>10</max_contacts>
        </collision>
        <visual name='visual_9'>
          <pose>0.975 -1.3 0 0 0 -1.5708</pose>
          <geometry>
            <mesh>
              <uri>model://miro_football_pitch/meshes/cqr_panel.dae</uri>
            </mesh>
          </geometry>
        </visual>
        <collision name='collision_9'>
          <pose>0.975 -1.3 0 0 0 -1.5708</pose>
          <geometry>
            <mesh>
              <uri>model://miro_football_pitch/meshes/cqr_panel.dae</uri>
            </mesh>
          </geometry>
          <surface>
            <friction>
              <ode>
                <mu>0.1</mu>
                <mu2>0.1</mu2>
              </ode>
              <torsional>
                <ode/>
              </torsional>
            </friction>
            <contact>
              <ode/>
            </contact>
            <bounce/>
          </surface>
          <max_contacts>10</max_contacts>
        </collision>
        <visual name='visual_10'>
          <pose>1.625 1.3 0 0 -0 1.5708</pose>
          <geometry>
            <mesh>
              <uri>model://miro_football_pitch/meshes/cqr_panel.dae</uri>
            </mesh>
          </geometry>
        </visual>
        <collision name='collision_10'>
          <pose>1.625 1.3 0 0 -0 1.5708</pose>
          <geometry>
            <mesh>
              <uri>model://miro_football_pitch/meshes/cqr_panel.dae</uri>
            </mesh>
          </geometry>
          <surface>
            <friction>
              <ode>
                <mu>0.1</mu>
                <mu2>0.1</mu2>
              </ode>
              <torsional>
                <ode/>
              </torsional>
            </friction>
            <contact>
              <ode/>
            </contact>
            <bounce/>
          </surface>
          <max_contacts>10</max_contacts>
        </collision>
        <visual name='visual_11'>
          <pose>1.625 -1.3 0 0 0 -1.5708</pose>
          <geometry>
            <mesh>
              <uri>model://miro_football_pitch/meshes/cqr_panel.dae</uri>
            </mesh>
          </geometry>
        </visual>
        <collision name='collision_11'>
          <pose>1.625 -1.3 0 0 0 -1.5708</pose>
          <geometry>
            <mesh>
              <uri>model://miro_football_pitch/meshes/cqr_panel.dae</uri>
            </mesh>
          </geometry>
          <surface>
            <friction>
              <ode>
                <mu>0.1</mu>
                <mu2>0.1</mu2>
              </ode>
              <torsional>
                <ode/>
              </torsional>
            </friction>
            <contact>
              <ode/>
            </contact>
            <bounce/>
          </surface>
          <max_contacts>10</max_contacts>
        </collision>
        <visual name='visual_12'>
          <pose>1.95 -0.975 0 0 -0 0</pose>
          <geometry>
            <mesh>
              <uri>model://miro_football_pitch/meshes/cqr_panel.dae</uri>
            </mesh>
          </geometry>
        </visual>
        <collision name='collision_12'>
          <pose>1.95 -0.975 0 0 -0 0</pose>
          <geometry>
            <mesh>
              <uri>model://miro_football_pitch/meshes/cqr_panel.dae</uri>
            </mesh>
          </geometry>
          <surface>
            <friction>
              <ode>
                <mu>0.1</mu>
                <mu2>0.1</mu2>
              </ode>
              <torsional>
                <ode/>
              </torsional>
            </friction>
            <contact>
              <ode/>
            </contact>
            <bounce/>
          </surface>
          <max_contacts>10</max_contacts>
        </collision>
        <visual name='visual_13'>
          <pose>-1.95 -0.975 0 0 -0 -3.14159</pose>
          <geometry>
            <mesh>
              <uri>model://miro_football_pitch/meshes/cqr_panel.dae</uri>
            </mesh>
          </geometry>
        </visual>
        <collision name='collision_13'>
          <pose>-1.95 -0.975 0 0 -0 -3.14159</pose>
          <geometry>
            <mesh>
              <uri>model://miro_football_pitch/meshes/cqr_panel.dae</uri>
            </mesh>
          </geometry>
          <surface>
            <friction>
              <ode>
                <mu>0.1</mu>
                <mu2>0.1</mu2>
              </ode>
              <torsional>
                <ode/>
              </torsional>
            </friction>
            <contact>
              <ode/>
            </contact>
            <bounce/>
          </surface>
          <max_contacts>10</max_contacts>
        </collision>
        <visual name='visual_14'>
          <pose>1.95 -0.325 0 0 -0 0</pose>
          <geometry>
            <mesh>
              <uri>model://miro_football_pitch/meshes/cqr_panel.dae</uri>
            </mesh>
          </geometry>
        </visual>
        <collision name='collision_14'>
          <pose>1.95 -0.325 0 0 -0 0</pose>
          <geometry>
            <mesh>
              <uri>model://miro_football_pitch/meshes/cqr_panel.dae</uri>
            </mesh>
          </geometry>
          <surface>
            <friction>
              <ode>
                <mu>0.1</mu>
                <mu2>0.1</mu2>
              </ode>
              <torsional>
                <ode/>
              </torsional>
            </friction>
            <contact>
              <ode/>
            </contact>
            <bounce/>
          </surface>
          <max_contacts>10</max_contacts>
        </collision>
        <visual name='visual_15'>
          <pose>-1.95 -0.325 0 0 -0 -3.14159</pose>
          <geometry>
            <mesh>
              <uri>model://miro_football_pitch/meshes/cqr_panel.dae</uri>
            </mesh>
          </geometry>
        </visual>
        <collision name='collision_15'>
          <pose>-1.95 -0.325 0 0 -0 -3.14159</pose>
          <geometry>
            <mesh>
              <uri>model://miro_football_pitch/meshes/cqr_panel.dae</uri>
            </mesh>
          </geometry>
          <surface>
            <friction>
              <ode>
                <mu>0.1</mu>
                <mu2>0.1</mu2>
              </ode>
              <torsional>
                <ode/>
              </torsional>
            </friction>
            <contact>
              <ode/>
            </contact>
            <bounce/>
          </surface>
          <max_contacts>10</max_contacts>
        </collision>
        <visual name='visual_16'>
          <pose>1.95 0.325 0 0 -0 0</pose>
          <geometry>
            <mesh>
              <uri>model://miro_football_pitch/meshes/cqr_panel.dae</uri>
            </mesh>
          </geometry>
        </visual>
        <collision name='collision_16'>
          <pose>1.95 0.325 0 0 -0 0</pose>
          <geometry>
            <mesh>
              <uri>model://miro_football_pitch/meshes/cqr_panel.dae</uri>
            </mesh>
          </geometry>
          <surface>
            <friction>
              <ode>
                <mu>0.1</mu>
                <mu2>0.1</mu2>
              </ode>
              <torsional>
                <ode/>
              </torsional>
            </friction>
            <contact>
              <ode/>
            </contact>
            <bounce/>
          </surface>
          <max_contacts>10</max_contacts>
        </collision>
        <visual name='visual_17'>
          <pose>-1.95 0.325 0 0 -0 -3.14159</pose>
          <geometry>
            <mesh>
              <uri>model://miro_football_pitch/meshes/cqr_panel.dae</uri>
            </mesh>
          </geometry>
        </visual>
        <collision name='collision_17'>
          <pose>-1.95 0.325 0 0 -0 -3.14159</pose>
          <geometry>
            <mesh>
              <uri>model://miro_football_pitch/meshes/cqr_panel.dae</uri>
            </mesh>
          </geometry>
          <surface>
            <friction>
              <ode>
                <mu>0.1</mu>
                <mu2>0.1</mu2>
              </ode>
              <torsional>
                <ode/>
              </torsional>
            </friction>
            <contact>
              <ode/>
            </contact>
            <bounce/>
          </surface>
          <max_contacts>10</max_contacts>
        </collision>
        <visual name='visual_18'>
          <pose>1.95 0.975 0 0 -0 0</pose>
          <geometry>
            <mesh>
              <uri>model://miro_football_pitch/meshes/cqr_panel.dae</uri>
            </mesh>
          </geometry>
        </visual>
        <collision name='collision_18'>
          <pose>1.95 0.975 0 0 -0 0</pose>
          <geometry>
            <mesh>
              <uri>model://miro_football_pitch/meshes/cqr_panel.dae</uri>
            </mesh>
          </geometry>
          <surface>
            <friction>
              <ode>
                <mu>0.1</mu>
                <mu2>0.1</mu2>
              </ode>
              <torsional>
                <ode/>
              </torsional>
            </friction>
            <contact>
              <ode/>
            </contact>
            <bounce/>
          </surface>
          <max_contacts>10</max_contacts>
        </collision>
        <visual name='visual_19'>
          <pose>-1.95 0.975 0 0 -0 -3.14159</pose>
          <geometry>
            <mesh>
              <uri>model://miro_football_pitch/meshes/cqr_panel.dae</uri>
            </mesh>
          </geometry>
        </visual>
        <collision name='collision_19'>
          <pose>-1.95 0.975 0 0 -0 -3.14159</pose>
          <geometry>
            <mesh>
              <uri>model://miro_football_pitch/meshes/cqr_panel.dae</uri>
            </mesh>
          </geometry>
          <surface>
            <friction>
              <ode>
                <mu>0.1</mu>
                <mu2>0.1</mu2>
              </ode>
              <torsional>
                <ode/>
              </torsional>
            </friction>
            <contact>
              <ode/>
            </contact>
            <bounce/>
          </surface>
          <max_contacts>10</max_contacts>
        </collision>
        <visual name='visual_20'>
          <pose>0 0 0 0 -0 0</pose>
          <geometry>
            <box>
              <size>3.9 2.6 0.01</size>
            </box>
          </geometry>
          <material>
            <script>
              <uri>file://media/materials/scripts/gazebo.material</uri>
              <name>Gazebo/Green</name>
            </script>
          </material>
        </visual>
        <collision name='collision_20'>
          <pose>0 0 0 0 -0 0</pose>
          <geometry>
            <box>
              <size>3.9 2.6 0.01</size>
            </box>
          </geometry>
          <surface>
            <friction>
              <ode>
                <mu>1</mu>
                <mu2>1</mu2>
              </ode>
              <torsional>
                <ode/>
              </torsional>
            </friction>
            <contact>
              <ode/>
            </contact>
            <bounce/>
          </surface>
          <max_contacts>10</max_contacts>
        </collision>
        <self_collide>0</self_collide>
        <enable_wind>0</enable_wind>
        <kinematic>0</kinematic>
      </link>
      <pose>-0.021025 -0.006056 0 0 -0 0</pose>
    </model>
    <model name='unit_cylinder'>
      <pose>0.270306 0.078937 0.5 0 -0 0</pose>
      <link name='link'>
        <inertial>
          <mass>1</mass>
          <inertia>
            <ixx>0.145833</ixx>
            <ixy>0</ixy>
            <ixz>0</ixz>
            <iyy>0.145833</iyy>
            <iyz>0</iyz>
            <izz>0.125</izz>
          </inertia>
          <pose>0 0 0 0 -0 0</pose>
        </inertial>
        <collision name='collision'>
          <geometry>
            <cylinder>
              <radius>0.499998</radius>
              <length>1</length>
            </cylinder>
          </geometry>
          <max_contacts>10</max_contacts>
          <surface>
            <contact>
              <ode/>
            </contact>
            <bounce/>
            <friction>
              <torsional>
                <ode/>
              </torsional>
              <ode/>
            </friction>
          </surface>
        </collision>
        <visual name='visual'>
          <geometry>
            <cylinder>
              <radius>0.499998</radius>
              <length>1</length>
            </cylinder>
          </geometry>
          <material>
            <script>
              <name>Gazebo/Grey</name>
              <uri>file://media/materials/scripts/gazebo.material</uri>
            </script>
          </material>
        </visual>
        <self_collide>0</self_collide>
        <enable_wind>0</enable_wind>
        <kinematic>0</kinematic>
      </link>
    </model>
    <model name='unit_cylinder_clone'>
      <pose>0.873739 -0.536574 0.499975 7.3e-05 -8e-06 -0.000403</pose>
      <link name='link'>
        <inertial>
          <mass>1</mass>
          <inertia>
            <ixx>0.145833</ixx>
            <ixy>0</ixy>
            <ixz>0</ixz>
            <iyy>0.145833</iyy>
            <iyz>0</iyz>
            <izz>0.125</izz>
          </inertia>
          <pose>0 0 0 0 -0 0</pose>
        </inertial>
        <collision name='collision'>
          <geometry>
            <cylinder>
              <radius>0.104731</radius>
              <length>1</length>
            </cylinder>
          </geometry>
          <max_contacts>10</max_contacts>
          <surface>
            <contact>
              <ode/>
            </contact>
            <bounce/>
            <friction>
              <torsional>
                <ode/>
              </torsional>
              <ode/>
            </friction>
          </surface>
        </collision>
        <visual name='visual'>
          <geometry>
            <cylinder>
              <radius>0.104731</radius>
              <length>1</length>
            </cylinder>
          </geometry>
          <material>
            <script>
              <name>Gazebo/Grey</name>
              <uri>file://media/materials/scripts/gazebo.material</uri>
            </script>
          </material>
        </visual>
        <self_collide>0</self_collide>
        <enable_wind>0</enable_wind>
        <kinematic>0</kinematic>
      </link>
    </model>
    <model name='unit_cylinder_clone_clone'>
      <pose>0.848752 0.638075 0.499974 5.7e-05 -3.2e-05 -0.000345</pose>
      <link name='link'>
        <inertial>
          <mass>1</mass>
          <inertia>
            <ixx>0.145833</ixx>
            <ixy>0</ixy>
            <ixz>0</ixz>
            <iyy>0.145833</iyy>
            <iyz>0</iyz>
            <izz>0.125</izz>
          </inertia>
          <pose>0 0 0 0 -0 0</pose>
        </inertial>
        <collision name='collision'>
          <geometry>
            <cylinder>
              <radius>0.104731</radius>
              <length>1</length>
            </cylinder>
          </geometry>
          <max_contacts>10</max_contacts>
          <surface>
            <contact>
              <ode/>
            </contact>
            <bounce/>
            <friction>
              <torsional>
                <ode/>
              </torsional>
              <ode/>
            </friction>
          </surface>
        </collision>
        <visual name='visual'>
          <geometry>
            <cylinder>
              <radius>0.104731</radius>
              <length>1</length>
            </cylinder>
          </geometry>
          <material>
            <script>
              <name>Gazebo/Grey</name>
              <uri>file://media/materials/scripts/gazebo.material</uri>
            </script>
          </material>
        </visual>
        <self_collide>0</self_collide>
        <enable_wind>0</enable_wind>
        <kinematic>0</kinematic>
      </link>
    </model>
    <model name='unit_cylinder_clone_clone_clone'>
      <pose>1.50144 0.011697 0.499971 1.7e-05 -4e-05 -0.000256</pose>
      <link name='link'>
        <inertial>
          <mass>1</mass>
          <inertia>
            <ixx>0.145833</ixx>
            <ixy>0</ixy>
            <ixz>0</ixz>
            <iyy>0.145833</iyy>
            <iyz>0</iyz>
            <izz>0.125</izz>
          </inertia>
          <pose>0 0 0 0 -0 0</pose>
        </inertial>
        <collision name='collision'>
          <geometry>
            <cylinder>
              <radius>0.104731</radius>
              <length>1</length>
            </cylinder>
          </geometry>
          <max_contacts>10</max_contacts>
          <surface>
            <contact>
              <ode/>
            </contact>
            <bounce/>
            <friction>
              <torsional>
                <ode/>
              </torsional>
              <ode/>
            </friction>
          </surface>
        </collision>
        <visual name='visual'>
          <geometry>
            <cylinder>
              <radius>0.104731</radius>
              <length>1</length>
            </cylinder>
          </geometry>
          <material>
            <script>
              <name>Gazebo/Grey</name>
              <uri>file://media/materials/scripts/gazebo.material</uri>
            </script>
          </material>
        </visual>
        <self_collide>0</self_collide>
        <enable_wind>0</enable_wind>
        <kinematic>0</kinematic>
      </link>
    </model>
    <state world_name='default'>
      <sim_time>364 579000000</sim_time>
      <real_time>460 507888300</real_time>
      <wall_time>1652700517 75836600</wall_time>
      <iterations>364579</iterations>
      <model name='ground_plane'>
        <pose>0 0 -1 0 -0 0</pose>
        <scale>1 1 1</scale>
        <link name='link'>
          <pose>0 0 -1 0 -0 0</pose>
          <velocity>0 0 0 0 -0 0</velocity>
          <acceleration>0 0 0 0 -0 0</acceleration>
          <wrench>0 0 0 0 -0 0</wrench>
        </link>
      </model>
      <model name='miro'>
        <pose>-1.01171 0.007589 0.000331 3e-05 -0.108205 0.110542</pose>
        <scale>1 1 1</scale>
        <link name='miro_body::body'>
          <pose>-1.01171 0.007589 0.000331 3e-05 -0.108205 0.110542</pose>
          <velocity>-0.000229 0.002234 1.7e-05 0.059756 0.006483 -0.000652</velocity>
          <acceleration>0.075033 -0.583232 0.013852 -0.426057 0.33538 2.50881</acceleration>
          <wrench>0.117862 -0.916141 0.021759 0 -0 0</wrench>
        </link>
        <link name='miro_body::wheel_lh'>
          <pose>-1.01383 0.00734 0.000198 -0.000241 -0.058202 0.111864</pose>
          <velocity>-5.4e-05 4.5e-05 0.002705 0.027573 0.003813 -0.000641</velocity>
          <acceleration>0.354324 -2.3615 9.74361 -1.39896 1.33444 -1.76184</acceleration>
          <wrench>0.047494 -0.316538 1.30604 0 -0 0</wrench>
        </link>
        <link name='miro_body::wheel_rh'>
          <pose>-1.01383 0.007364 0.000195 0.000268 -0.05817 0.109225</pose>
          <velocity>7.5e-05 5.8e-05 -0.002757 0.027135 0.002116 -0.000385</velocity>
          <acceleration>0.228697 -2.32282 -9.74954 0.860432 -1.09671 1.89047</acceleration>
          <wrench>0.030655 -0.311354 -1.30684 0 -0 0</wrench>
        </link>
        <link name='miro_gmbl::gmbl'>
          <pose>-1.05735 0.002521 0.007652 1.2e-05 0.47385 0.110548</pose>
          <velocity>0.000226 -0.00083 -3e-06 0.02025 0.001713 -0.006732</velocity>
          <acceleration>1.13273 -8.88832 0.045466 1.52205 1.18723 -0.250848</acceleration>
          <wrench>0.044482 -0.349044 0.001785 0 -0 0</wrench>
        </link>
        <link name='miro_head::ear_lh'>
          <pose>-1.04375 0.026073 -0.000153 0.044362 0.394577 -0.027734</pose>
          <velocity>0.001179 -0.013588 -0.000983 -0.042506 -0.006069 0.028799</velocity>
          <acceleration>-2.75124 0.065204 -3.99925 2.88971 0.98312 0.571</acceleration>
          <wrench>-0.15558 0.003687 -0.226153 0 -0 0</wrench>
        </link>
        <link name='miro_head::ear_rh'>
          <pose>-1.03976 -0.016673 0.000127 -0.042278 0.397707 0.242862</pose>
          <velocity>0.002374 -0.013386 0.000865 -0.042017 -0.005828 0.028915</velocity>
          <acceleration>2.69834 0.56207 4.0974 -2.41346 1.46893 0.790738</acceleration>
          <wrench>0.152589 0.031784 0.231704 0 -0 0</wrench>
        </link>
        <link name='miro_head::eyelid_lh'>
          <pose>-1.00477 0.075375 -0.021358 0.288146 0.196277 0.190683</pose>
          <velocity>0.000408 -0.012633 -0.002955 -0.039496 -0.008295 0.029097</velocity>
          <acceleration>-1.58488 -1.45304 -2.57137 -0.513927 0.328728 -1.97563</acceleration>
          <wrench>-0.026555 -0.024346 -0.043083 0 -0 0</wrench>
        </link>
        <link name='miro_head::eyelid_rh'>
          <pose>-0.958288 -0.084904 -0.022676 -0.406152 0.06915 0.021658</pose>
          <velocity>0.003779 -0.011441 0.004209 -0.039925 -0.002955 0.028938</velocity>
          <acceleration>2.08105 -1.0704 2.93172 1.77076 0.92634 0.846877</acceleration>
          <wrench>0.034868 -0.017935 0.049121 0 -0 0</wrench>
        </link>
        <link name='miro_head::head'>
          <pose>-1.05655 0.002603 0.007253 -2.2e-05 0.4694 0.11055</pose>
          <velocity>0.001785 -0.013533 -5.3e-05 -0.041537 -0.005867 0.028806</velocity>
          <acceleration>0.696108 -5.01318 0.09614 -1.45376 1.38576 0.583175</acceleration>
          <wrench>0.18224 -1.31244 0.025169 0 -0 0</wrench>
        </link>
        <link name='miro_neck::neck'>
          <pose>-1.05734 0.002524 0.007652 1.6e-05 0.47384 0.110539</pose>
          <velocity>-0.000336 0.003386 1.3e-05 0.029429 0.002861 -0.029652</velocity>
          <acceleration>0.48476 -4.35777 0.057196 -2.34891 -1.18974 1.5621</acceleration>
          <wrench>0.03655 -0.328567 0.004312 0 -0 0</wrench>
        </link>
        <link name='miro_tail::tail'>
          <pose>-1.01209 0.00791 -0.000425 -0.000232 -0.103205 0.113083</pose>
          <velocity>-0.000259 0.002333 -4e-06 0.059228 0.006697 -0.000151</velocity>
          <acceleration>0.389106 -3.48846 -0.014021 -0.923267 0.827997 -0.784288</acceleration>
          <wrench>0.022004 -0.197269 -0.000793 0 -0 0</wrench>
        </link>
        <link name='miro_tail::tail_gmbl'>
          <pose>-1.01205 0.00755 -0.000425 2.9e-05 -0.103205 0.110542</pose>
          <velocity>-0.000262 0.002354 -2.5e-05 0.059473 0.006724 -0.000141</velocity>
          <acceleration>0.388499 -3.48269 -0.014075 -0.433713 0.882337 -0.762447</acceleration>
          <wrench>0.021969 -0.196943 -0.000796 0 -0 0</wrench>
        </link>
      </model>
      <model name='miro_football_pitch'>
        <pose>-0.016082 0.024306 -0.005033 0 -0 0</pose>
        <scale>1 1 1</scale>
        <link name='main'>
          <pose>-0.016082 0.024306 -0.005033 0 -0 0</pose>
          <velocity>0 0 0 0 -0 0</velocity>
          <acceleration>0 0 0 0 -0 0</acceleration>
          <wrench>0 0 0 0 -0 0</wrench>
        </link>
      </model>
      <model name='unit_cylinder'>
        <pose>-0.073652 0.014595 0.499964 6.7e-05 0 -0.00159</pose>
        <scale>0.209463 0.209463 1</scale>
        <link name='link'>
          <pose>-0.073652 0.014595 0.499964 6.7e-05 0 -0.00159</pose>
          <velocity>0 0 0 0 -0 0</velocity>
          <acceleration>0 0 -9.8 -0 -0 -0</acceleration>
          <wrench>0 0 -9.8 0 -0 0</wrench>
        </link>
      </model>
      <model name='unit_cylinder_clone'>
        <pose>0.560873 -0.596288 0.499974 6.8e-05 -8e-06 -0.000572</pose>
        <scale>1 1 1</scale>
        <link name='link'>
          <pose>0.560873 -0.596288 0.499974 6.8e-05 -8e-06 -0.000572</pose>
          <velocity>0 0 0 0 -0 0</velocity>
          <acceleration>-0.100416 -0.419092 19.4181 0.851692 -0.210578 0.084612</acceleration>
          <wrench>-0.100416 -0.419092 19.4181 0 -0 0</wrench>
        </link>
      </model>
      <model name='unit_cylinder_clone_clone'>
        <pose>0.559356 0.638122 0.499962 2e-05 -4.5e-05 0.000204</pose>
        <scale>1 1 1</scale>
        <link name='link'>
          <pose>0.559356 0.638122 0.499962 2e-05 -4.5e-05 0.000204</pose>
          <velocity>0 0 0 0 -0 0</velocity>
          <acceleration>0 0 -9.8 -0 -0 -0</acceleration>
          <wrench>0 0 -9.8 0 -0 0</wrench>
        </link>
      </model>
      <model name='unit_cylinder_clone_clone_clone'>
        <pose>1.21243 0.011773 0.499971 1.4e-05 -3.8e-05 -0.000144</pose>
        <scale>1 1 1</scale>
        <link name='link'>
          <pose>1.21243 0.011773 0.499971 1.4e-05 -3.8e-05 -0.000144</pose>
          <velocity>0 0 0 0 -0 0</velocity>
          <acceleration>-1.52044 -1.12647 19.5859 -0.936558 -0.06685 2.88413</acceleration>
          <wrench>-1.52044 -1.12647 19.5859 0 -0 0</wrench>
        </link>
      </model>
      <light name='sun'>
        <pose>0 0 10 0 -0 0</pose>
      </light>
    </state>
  </world>
</sdf>
